{"name": "test_post_param[param_error12]", "status": "failed", "statusDetails": {"message": "Failed: API ERROR", "trace": "method = 'POST', url = 'https://gorest.co.in/public/v2/users'\nr_json = {'email': 'test_auto_4046@gmail.com', 'gender': 'male', 'name1': 'c_p_s', 'status': 'active'}\nheaders = {'Authorization': 'Bearer d76528d3edeb70ab3d775d9f11a4963181b94d9e0ec17d996ed8ddb2d6cb5f22', 'Content-Type': 'application/json'}, status = 201\n\n    def call_api_custom(method, url, r_json = None, headers = None, status = None):\n        response = requests.request(method, url,json = r_json,headers= headers)\n        try:\n>           assert response.status_code == status, f\"API ERROR, status code is {response.status_code}\"\nE           AssertionError: API ERROR, status code is 422\n\ncustom_call.py:6: AssertionError\n\nDuring handling of the above exception, another exception occurred:\n\nparam_error1 = {'email': 'test_auto_4046@gmail.com', 'gender': 'male', 'name1': 'c_p_s', 'status': 'active'}\n\n    def test_post_param(param_error1):\n        url = api_url.GET_URL\n        headers = common_utility.get_header()\n        c = param_error1\n        c[\"email\"] = common_utility.get_email()\n>       response = custom_call.call_api_custom(\"POST\", url, headers=headers, r_json=c, status=201)\n\ntest_script3.py:38: \n_ _ _ _ _ _ _ _ _ _ _ _ _ _ _ _ _ _ _ _ _ _ _ _ _ _ _ _ _ _ _ _ _ _ _ _ _ _ _ _ _ _ _ _ _ _ _ _ _ _ _ _ _ _ _ _ _ _ _ _ _ _ _ _ _ _ _ _ _ _ _ _ _ _ _ _ _ _ _ _\n\nmethod = 'POST', url = 'https://gorest.co.in/public/v2/users'\nr_json = {'email': 'test_auto_4046@gmail.com', 'gender': 'male', 'name1': 'c_p_s', 'status': 'active'}\nheaders = {'Authorization': 'Bearer d76528d3edeb70ab3d775d9f11a4963181b94d9e0ec17d996ed8ddb2d6cb5f22', 'Content-Type': 'application/json'}, status = 201\n\n    def call_api_custom(method, url, r_json = None, headers = None, status = None):\n        response = requests.request(method, url,json = r_json,headers= headers)\n        try:\n            assert response.status_code == status, f\"API ERROR, status code is {response.status_code}\"\n            return response\n        except:\n>           pytest.fail(\"API ERROR\")\nE           Failed: API ERROR\n\ncustom_call.py:9: Failed"}, "parameters": [{"name": "param_error1", "value": "{'name1': 'c_p_s', 'email': 'pankaj1112131@gmail.com', 'gender': 'male', 'status': 'active'}"}], "start": 1713314984800, "stop": 1713314986746, "uuid": "c4812d3e-5ef7-4ad4-8b5c-259a0ace175c", "historyId": "ff03075cc29b4788a6220d4dadc4c95b", "testCaseId": "4a831de92a32bab33485f3f53395f863", "fullName": "test_script3#test_post_param", "labels": [{"name": "suite", "value": "test_script3"}, {"name": "host", "value": "HPENVY13"}, {"name": "thread", "value": "3220-MainThread"}, {"name": "framework", "value": "pytest"}, {"name": "language", "value": "cpython3"}, {"name": "package", "value": "test_script3"}]}