{"name": "test_put_param[param_error20]", "status": "failed", "statusDetails": {"message": "Failed: API ERROR", "trace": "method = 'PUT', url = 'https://gorest.co.in/public/v2/users/6856187'\nr_json = {'email': 'pankaj1112131@gmail.com', 'gender': 'male', 'name': 'u_p_d', 'option': 'test', ...}\nheaders = {'Authorization': 'Bearer d76528d3edeb70ab3d775d9f11a4963181b94d9e0ec17d996ed8ddb2d6cb5f22', 'Content-Type': 'application/json'}, status = 200\n\n    def call_api_custom(method, url, r_json = None, headers = None, status = None):\n        response = requests.request(method, url,json = r_json,headers= headers)\n        try:\n>           assert response.status_code == status, f\"API ERROR, status code is {response.status_code}\"\nE           AssertionError: API ERROR, status code is 422\n\ncustom_call.py:6: AssertionError\n\nDuring handling of the above exception, another exception occurred:\n\nparam_error2 = {'email': 'pankaj1112131@gmail.com', 'gender': 'male', 'name': 'u_p_d', 'option': 'test', ...}\n\n    def test_put_param(param_error2):\n        global id\n        id = post()\n        url = api_url.GET_URL + f\"/{id}\"\n        headers = common_utility.get_header()\n        u = param_error2\n>       response = custom_call.call_api_custom(\"PUT\", url, headers=headers, r_json=u, status=200)\n\ntest_script3.py:63: \n_ _ _ _ _ _ _ _ _ _ _ _ _ _ _ _ _ _ _ _ _ _ _ _ _ _ _ _ _ _ _ _ _ _ _ _ _ _ _ _ _ _ _ _ _ _ _ _ _ _ _ _ _ _ _ _ _ _ _ _ _ _ _ _ _ _ _ _ _ _ _ _ _ _ _ _ _ _ _ _\n\nmethod = 'PUT', url = 'https://gorest.co.in/public/v2/users/6856187'\nr_json = {'email': 'pankaj1112131@gmail.com', 'gender': 'male', 'name': 'u_p_d', 'option': 'test', ...}\nheaders = {'Authorization': 'Bearer d76528d3edeb70ab3d775d9f11a4963181b94d9e0ec17d996ed8ddb2d6cb5f22', 'Content-Type': 'application/json'}, status = 200\n\n    def call_api_custom(method, url, r_json = None, headers = None, status = None):\n        response = requests.request(method, url,json = r_json,headers= headers)\n        try:\n            assert response.status_code == status, f\"API ERROR, status code is {response.status_code}\"\n            return response\n        except:\n>           pytest.fail(\"API ERROR\")\nE           Failed: API ERROR\n\ncustom_call.py:9: Failed"}, "parameters": [{"name": "param_error2", "value": "{'name': 'u_p_d', 'email': 'pankaj1112131@gmail.com', 'option': 'test', 'gender': 'male', 'status': 'active'}"}], "start": 1713314986777, "stop": 1713314988924, "uuid": "aab10d69-1c1e-432f-8bae-5cefc23621e6", "historyId": "b88426d398ec0c674a406c5dfbe97fa1", "testCaseId": "05fd289c4b438f5d0e59befe96d02baf", "fullName": "test_script3#test_put_param", "labels": [{"name": "suite", "value": "test_script3"}, {"name": "host", "value": "HPENVY13"}, {"name": "thread", "value": "3220-MainThread"}, {"name": "framework", "value": "pytest"}, {"name": "language", "value": "cpython3"}, {"name": "package", "value": "test_script3"}]}