{"name": "test_post_data[data_error2]", "status": "failed", "statusDetails": {"message": "Failed: API ERROR", "trace": "method = 'POST', url = 'https://gorest.co.in/public/v2/users', r_json = {'email': 'c_d_email', 'gender': 'male', 'name': 'c_d_email_2', 'status': 'active'}\nheaders = {'Authorization': 'Bearer d76528d3edeb70ab3d775d9f11a4963181b94d9e0ec17d996ed8ddb2d6cb5f22', 'Content-Type': 'application/json'}, status = 201\n\n    def call_api_custom(method, url, r_json = None, headers = None, status = None):\n        response = requests.request(method, url,json = r_json,headers= headers)\n        try:\n>           assert response.status_code == status, f\"API ERROR, status code is {response.status_code}\"\nE           AssertionError: API ERROR, status code is 422\n\ncustom_call.py:6: AssertionError\n\nDuring handling of the above exception, another exception occurred:\n\ndata_error = {'email': 'c_d_email', 'gender': 'male', 'name': 'c_d_email_2', 'status': 'active'}\n\n    def test_post_data(data_error):\n        url = api_url.GET_URL\n        headers = common_utility.get_header()\n        c_u = data_error\n        if(c_u == file.read_file(\"C:\\\\api-testing\\\\config\\\\c_d_id.json\")):\n            c_u[\"email\"] = common_utility.get_email()\n>       response = custom_call.call_api_custom(\"POST\", url, headers=headers, r_json=c_u, status=201)\n\ntest_script4.py:26: \n_ _ _ _ _ _ _ _ _ _ _ _ _ _ _ _ _ _ _ _ _ _ _ _ _ _ _ _ _ _ _ _ _ _ _ _ _ _ _ _ _ _ _ _ _ _ _ _ _ _ _ _ _ _ _ _ _ _ _ _ _ _ _ _ _ _ _ _ _ _ _ _ _ _ _ _ _ _ _ _\n\nmethod = 'POST', url = 'https://gorest.co.in/public/v2/users', r_json = {'email': 'c_d_email', 'gender': 'male', 'name': 'c_d_email_2', 'status': 'active'}\nheaders = {'Authorization': 'Bearer d76528d3edeb70ab3d775d9f11a4963181b94d9e0ec17d996ed8ddb2d6cb5f22', 'Content-Type': 'application/json'}, status = 201\n\n    def call_api_custom(method, url, r_json = None, headers = None, status = None):\n        response = requests.request(method, url,json = r_json,headers= headers)\n        try:\n            assert response.status_code == status, f\"API ERROR, status code is {response.status_code}\"\n            return response\n        except:\n>           pytest.fail(\"API ERROR\")\nE           Failed: API ERROR\n\ncustom_call.py:9: Failed"}, "parameters": [{"name": "data_error", "value": "{'name': 'c_d_email_2', 'email': 'c_d_email', 'gender': 'male', 'status': 'active'}"}], "start": 1713315080734, "stop": 1713315081686, "uuid": "d7e74757-673f-4e9d-873c-bfdfef3a8e15", "historyId": "3f36e3c1b761194a64f12ed8b10bd58b", "testCaseId": "e9d60a2a2aa5a7d8b678998bf380761e", "fullName": "test_script4#test_post_data", "labels": [{"name": "suite", "value": "test_script4"}, {"name": "host", "value": "HPENVY13"}, {"name": "thread", "value": "6084-MainThread"}, {"name": "framework", "value": "pytest"}, {"name": "language", "value": "cpython3"}, {"name": "package", "value": "test_script4"}]}