{"name": "test_delete_auth[auth_error_header1]", "status": "failed", "statusDetails": {"message": "Failed: API ERROR", "trace": "method = 'DELETE', url = 'https://gorest.co.in/public/v2/users/6856184', r_json = None\nheaders = {'Authorization': 'Bearer 18661386073d8ec7e241a5395233b5ce5457a4a7acca76f0a37f0ff14e057a7b1', 'Content-Type': 'application/json'}, status = 204\n\n    def call_api_custom(method, url, r_json = None, headers = None, status = None):\n        response = requests.request(method, url,json = r_json,headers= headers)\n        try:\n>           assert response.status_code == status, f\"API ERROR, status code is {response.status_code}\"\nE           AssertionError: API ERROR, status code is 401\n\ncustom_call.py:6: AssertionError\n\nDuring handling of the above exception, another exception occurred:\n\nauth_error_header = {'Authorization': 'Bearer 18661386073d8ec7e241a5395233b5ce5457a4a7acca76f0a37f0ff14e057a7b1', 'Content-Type': 'application/json'}\n\n    def test_delete_auth(auth_error_header):\n        global id\n        global id_1\n        global id_2\n        if(auth_error_header == common_utility.get_header_error2()):\n            id = id_2\n        if(auth_error_header == common_utility.get_header_error1()):\n            id = id_1\n        url = api_url.GET_URL + f\"/{id}\"\n        headers = auth_error_header\n>       response = custom_call.call_api_custom(\"DELETE\", url, headers=headers, status=204)\n\ntest_script2.py:85: \n_ _ _ _ _ _ _ _ _ _ _ _ _ _ _ _ _ _ _ _ _ _ _ _ _ _ _ _ _ _ _ _ _ _ _ _ _ _ _ _ _ _ _ _ _ _ _ _ _ _ _ _ _ _ _ _ _ _ _ _ _ _ _ _ _ _ _ _ _ _ _ _ _ _ _ _ _ _ _ _\n\nmethod = 'DELETE', url = 'https://gorest.co.in/public/v2/users/6856184', r_json = None\nheaders = {'Authorization': 'Bearer 18661386073d8ec7e241a5395233b5ce5457a4a7acca76f0a37f0ff14e057a7b1', 'Content-Type': 'application/json'}, status = 204\n\n    def call_api_custom(method, url, r_json = None, headers = None, status = None):\n        response = requests.request(method, url,json = r_json,headers= headers)\n        try:\n            assert response.status_code == status, f\"API ERROR, status code is {response.status_code}\"\n            return response\n        except:\n>           pytest.fail(\"API ERROR\")\nE           Failed: API ERROR\n\ncustom_call.py:9: Failed"}, "parameters": [{"name": "auth_error_header", "value": "{'Content-Type': 'application/json', 'Authorization': 'Bearer 18661386073d8ec7e241a5395233b5ce5457a4a7acca76f0a37f0ff14e057a7b1'}"}], "start": 1713314919313, "stop": 1713314920120, "uuid": "5d726fc0-e437-45d6-8a11-d8d947c9f008", "historyId": "adba8fe03893da73f0e5c784738dfdcb", "testCaseId": "f485e24547c19276693c5afc6930cf64", "fullName": "test_script2#test_delete_auth", "labels": [{"name": "suite", "value": "test_script2"}, {"name": "host", "value": "HPENVY13"}, {"name": "thread", "value": "16724-MainThread"}, {"name": "framework", "value": "pytest"}, {"name": "language", "value": "cpython3"}, {"name": "package", "value": "test_script2"}]}